Workbook
Name \a: #N/A
Name \b: #N/A
Name \p: #N/A
Name \z: #N/A
Name _______________day3: #REF!
Name _______________day3: #REF!
Name _______________day3: #REF!
Name _______________day3: #REF!
Name _______________day4: #REF!
Name _______________day4: #REF!
Name _______________day4: #REF!
Name _______________day4: #REF!
Name ______________A999999: #REF!
Name ______________A999999: #REF!
Name ______________day3: #REF!
Name ______________day3: #REF!
Name ______________day3: #REF!
Name ______________day3: #REF!
Name ______________day4: #REF!
Name ______________day4: #REF!
Name ______________day4: #REF!
Name ______________day4: #REF!
Name ______________SPO1: #N/A
Name ______________SPO2: #N/A
Name _____________A999999: #REF!
Name _____________A999999: #REF!
Name _____________day3: #REF!
Name _____________day3: #REF!
Name _____________day3: #REF!
Name _____________day3: #REF!
Name _____________day4: #REF!
Name _____________day4: #REF!
Name _____________day4: #REF!
Name _____________day4: #REF!
Name _____________SPO1: #N/A
Name _____________SPO2: #N/A
Name ____________A999999: #REF!
Name ____________A999999: #REF!
Name ____________day3: #REF!
Name ____________day3: #REF!
Name ____________day3: #REF!
Name ____________day3: #REF!
Name ____________day4: #REF!
Name ____________day4: #REF!
Name ____________day4: #REF!
Name ____________day4: #REF!
Name ____________SPO1: #N/A
Name ____________SPO2: #N/A
Name ___________A999999: #REF!
Name ___________A999999: #REF!
Name ___________day3: #REF!
Name ___________day3: #REF!
Name ___________day3: #REF!
Name ___________day3: #REF!
Name ___________day4: #REF!
Name ___________day4: #REF!
Name ___________day4: #REF!
Name ___________day4: #REF!
Name ___________SPO1: #N/A
Name ___________SPO2: #N/A

Sheet list01
B2: Фойда солиғи ҲИСОБ-КИТОБИ
B4: СТИР
C6: Ҳужжат тури: | F6: Ҳисобот даври | I6: чорак | J6: Солиқ даври
B8: Солиқ тўловчининг тўлиқ номи
B10: Солиқ тўловчининг жойлашган манзили
B12: Почта манзили
C14: Ходимларнинг ўртача йиллик сони | H14: шундан, ногиронлиги бўлган шахслар
B16: Бевосита харажатлар моддалари асосида товарлар (хизматлар) таннархи аниқланганда | H16: мутаносиб усул | J16: тўғридан-тўғри ҳисобга олиш усули | L16: ("1" рақами қўйилсин)
B17: Бевосита харажатлар суммаси асосида товарлар (хизматлар) таннархи анақланганда | H17: мутаносиб усул | J17: тўғридан-тўғри ҳисобга олиш усули
B19: Фойда солиғини | J19: ойидан бошлаб тўлайди.*
B21: Ҳисоб-китобни тақдим этиш муддати (кун/ой/йил)
K23: га тақдим этилади
D24: (cолиқ бўйича ҳисобга олиш жойидаги солиқ органи)
J26: Ўлчов бирлиги | K26: сўм
B28: Кўрсаткичлар (ўсиб борувчи тартибда тўлдирилади) | K28: Сатр коди | L28: Сумма
B29: Жами даромадлар (Ҳисоб-китобнинг 1-иловаси 010-сатри – 110-сатри – 121-сатри - 131-сатри - 150-сатри) | K29: 010
B30: Чегириладиган харажатлар (Ҳисоб-китобнинг 2-иловаси 010-сатри 3-устун - 4-устун ёки 2.1-иловаси 010-сатри 3-устун - 4-устун) | K30: 020
B31: Солиқ солинадиган фойда (010-сатр - 020-сатр) | K31: 030
B32: Имтиёзлар - жами (Ҳисоб-китобнинг 6-иловаси 030-сатри) | K32: 040
B33: Ноль ставка қўлланиладиган солиқ тўловчилар фойдаси (Ҳисоб-китобнинг 7-иловаси 030-сатри) | K33: 050
B34: Солиқ базаси (030-сатр – 040-сатр - 050-сатр), бироқ "0" дан кам эмас | K34: 060
B35: Жойлашган ҳудудга нисбатан пасайтирилган солиқ ставкалари бўйича солиқ солинадиган фойда | K35: 061
B36: Фойда солиғининг белгиланган ставкаси, фоизда | K36: 070
B37: Пасайтирилган солиқ ставкаси | K37: 071
B38: Ногиронлиги бўлган шахслар меҳнатидан фойдаланаётган юридик шахслар учун тузатилган солиқ ставкаси | K38: 072
B39: Фойда солиғи суммаси – жами | K39: 080
B40: Ушбу ҳисобот даврида ҳисобланган жами ойлик бўнак тўловлари | K40: 090
... B46: Фойда солиғининг бюджетга тўланиши лозим бўлган жами суммаси (080-сатр – 100-сатр – 110-сатр + 140-сатр - Ҳисоб-китобнинг 10-иловаси 090-сатри + Ҳисоб-китобнинг 11-иловаси 060-сатри) | K46: 150
B47: * Календарь йил давомида фойда солиғини тўлашга ўтган солиқ тўловчилар томонидан тўлдирилади.
B48: Изоҳлар.
B49: 1.061, 071-сатрлар ПФ-287 30.12.2022 й. 2 -банди а-кичик банди бўйича фойда ва пасайтирилган солиқ ставкалари
B50: 2. 072-сатрда ўзида ишловчиларнинг умумий ўртача йиллик сонининг 3 фоизидан кўпроғи ногиронлиги бўлган шахсларни ташкил этадиган юридик шахслар учун солиқ ставкаси ушбу моддада белгиланган нормадан ортиқча ишга жойлаштирилган ногиронларнинг ҳар бир фоизига солиқ ставкасининг бир фоизи ҳисобидан камайтирилади.
B51: 3. 110-сатрда доимий муассаса сифатида солиқ органида ҳисобга қўйишга қадар олинган даромадларини ҳисобга олиш, солиқ агенти томонидан солиқ ушлаб қолинганлигини тасдиқловчи ҳужжатлар мавжуд бўлган тақдирда амалга оширилади.
B52: 4. 090-сатр ўсиб бормайдиган тартибда жорий ҳисобот даврида ҳисобланган бўнак тўловлари кўрсатилади.
B54: Ушбу ҳисоб-китобда кўрсатилган маълумотларнинг тўлиқлиги ва ишончлилигини тасдиқлайман:
B55: Раҳбар | H55: Бош бухгалтер
B57: ЖШШИР | H57: ЖШШИР
B59: Ф. И. Ш. | H59: Ф. И. Ш.
B60: Имзо | H60: Имзо
B62: Тақдим этилган сана
...

Sheet list02
A1: lc=R60C6
B2: Ҳисоб-китобга 1-илова
C3: СТИР | D3: =list01!C4 -> 0
B4: Жами даромадлар
B5: Даромадлар рўйхати | C5: Сатр коди | D5: Сумма
B6: 1 | C6: 2 | D6: 3
B7: Жами даромадлар (020-сатр - 220-сатрлар йиғиндиси), шу жумладан | C7: 010 | D7: =SUM(D15:D36)+D8-D25-D27 -> 0
B8: Товарларни (хизматларни) реализация қилишдан олинган даромад (021-сатр - 026-сатрлар йиғиндиси), шу жумладан фаолият турлари кесимида | C8: 020 | D8: =SUM(D9:D14) -> 0
C9: 021
C10: 022
C11: 023
C12: 024
C13: 025
C14: 026
B15: Кредит (қарз, микрокредит ва бошқа молиявий операциялар) бўйича мукофот тарзидаги даромад | C15: 030
B16: Суғурта, қайта суғурта ташкилотининг суғурта, қайта суғурта қилиш шартномалари бўйича даромади | C16: 040
B17: Амортизация қилинадиган активларнинг ва бошқа мол-мулкнинг чиқиб кетишидан олинган даромад | C17: 050
B18: Мол-мулкни мулк ижарасига (ижарага) беришдан олинган даромад, бундан молиявий ижара (лизинг) мустасно | C18: 060
B19: Текин олинган мол-мулк (хизматлар), молиявий ёрдамлар | C19: 070
B20: Инвентаризация натижасида аниқланган ортиқча товар-моддий захираларнинг ва бошқа мол-мулкнинг қиймати тарзидаги даромад | C20: 080
B21: Қонунчилик ҳужжатларида белгиланган тартибда мажбуриятларни ҳисобдан чиқаришдан олинган даромад | C21: 090
B22: Талаб қилиш ҳуқуқидан ўзганинг фойдасига воз кечиш шартномаси бўйича олинган даромад | C22: 100
B23: Дивидендлар тарзидаги даромадлар | C23: 110
B24: Фоизлар тарзидаги даромадлар | C24: 120
B25: шу жумладан, солиқ агенти томонидан тўлов манбаида солиқ суммаси ушлаб қолинган | C25: 121
B26: Валюта курси фарқидан даромадлар | C26: 130
... B33: Ўзбекистон Республикаси Солиқ кодесининг 332-моддасида келтирилган ҳолларда даромадларга тузатиш киритиш | C33: 190
B34: Айрим операциялар бўйича даромадлар (Ҳисоб-китобнинг 9-иловаси 070-сатри 3-8 устунлар йиғиндиси) | C34: 200 | D34: =SUM(list13!F13:K13) -> 0
B35: Ўзбекистон Республикаси Солиқ кодексининг 347-моддаси 3-қисмида келтирилган даромадлар | C35: 210
B36: Ушбу илованинг 020-220-сатрларида кўрсатилмаган бошқа даромадлар (221-сатр - 228-сатрлар йиғиндиси), шу жумладан: | C36: 220 | D36: =SUM(D37:D44) -> 0
C37: 221
C38: 222
C39: 223
C40: 224
C41: 225
C42: 226
C43: 227
C44: 228
B45: Изоҳлар:
B46: 1. Агар айни бир даромадлар даромадларнинг бир нечта моддасида назарда тутилган бўлса, мазкур даромадлар фақат бир марта кўрсатилади.
...

Sheet list03
A1: lc=R80C6
B2: Ҳисоб-китобга 2-илова
D3: СТИР | E3: =list01!C4 -> 0
B4: Солиқ ҳисоби маълумотларига кўра харажатлар (зарарлар) * | C4: * | D4: =IF(SUM(D8:D9)*100.0001%<D10,"Ошибка",IF(D10<SUM(D8:D9)*0.9,"Ошибка",SUM(D8:D9))) -> 0 | E4: =IF(SUM(E8:E9)*100.0001%<E10,"Ошибка",IF(E10<SUM(E8:E9)*0.9,"Ошибка",SUM(E8:E9))) -> 0
B5: Солиқ солиш мақсадлари учун харажатлар (зарарлар) рўйхати | C5: Сатр коди | D5: Харажатлар (зарарлар) суммаси | E5: шундан, чегирилмайдиган харажатлар (зарарлар)
B6: 1 | C6: 2 | D6: 3 | E6: 4
B7: Жами харажатлар (020-сатр + 030-сатрлар йиғиндиси), шу жумладан: | C7: 010 | D7: =SUM(D8:D9) -> 0 | E7: =SUM(E8:E9) -> 0
B8: Сотилган товарлар (хизматлар) таннархи | C8: 020
B9: Бошқа харажатлар (зарарлар) | C9: 030
B10: 010-сатрига киритиладиган асосий харажатлар*: | C10: х | D10: =SUM(D11:D51)-D46-D25-D17-D30-D50 -> 0 | E10: =SUM(E11:E51)-E46-E25-E17-E30-E50 -> 0
B11: Сарфланган хом ашё ва материаллар (0102, 0103 сатрлардан ташқари) | C11: 0101
B12: Сарфланган ёқилғи харажатлари | C12: 0102
B13: Сарфланган табиий, суюлтирилган газ харажатлари | C13: 0103
B14: Сарфланган электр энергия харажатлари | C14: 0104
B15: Меҳнатга ҳақ тўлаш харажатлари ва ижтимоий солиқ бўйича харажатлар | C15: 0105
B16: Асосий воситалар ва номоддий активлар амортизацияси | C16: 0106
B17: шу жумладан қўлланилган инвестициявий чегирма | C17: 01061
B18: Қайта сотиш учун сотиб олинган товарлар қиймати | C18: 0107
B19: Машина ва асбоб-ускуналарни жорий таъмирлаш харажатлари | C19: 0108
B20: Маркетинг ва реклама харажатлари | C20: 0109
B21: Транспорт хизмати ва ташиш харажатлари | C21: 0110
B22: Оператив ижара бўйича харажатлар | C22: 0111
... B30: Трансферт нархни белгилаш натижасида оширилган харажат суммаси * | C30: 0118
B31: Солиқ тўловчининг Солиқ кодексининг 376-моддасида назарда тутилган жисмоний шахнинг моддий наф тарзидаги даромадлари ҳисобланган харажатлари | C31: 0119 | E31: =D31 -> 0
B32: Пенсияларга устамалар ва қўшимча тўловлар | C32: 0120 | E32: =D32 -> 0
B33: Ўзбекистон Республикаси Солиқ кодексининг 377-моддаси биринчи қисми 10-бандининг тўртинчи ва бешинчи хатбошиларида кўрсатилган моддий ёрдам | C33: 0121 | E33: =D33 -> 0
B34: хайрия ёрдамини амалга ошириш учун харажатлар, бундан меценатлик кўмагини кўрсатиш, ўқув-тарбия муассасаларига ёки етим болаларга ва ота-она қарамоғидан маҳрум бўлган болаларга моддий ёрдам кўрсатиш учун йўналтирилган маблағлар, шунингдек Болаларни қўллаб-қувватлаш жамоат фондига хайрия қилинган маблағлар мустасно | C34: 0122 | E34: =D34 -> 0
B35: Айбдорлари аниқланмаган талон-тарож қилишлар ва камомадлардан ёки айбдор тараф ҳисобидан зарур суммаларнинг ўрнини қоплаш имкони бўлмаган тақдирда кўрилган зарарлар | C35: 0123 | E35: =D35 -> 0
B36: Бошқа шахслар учун тўланган солиқлар | C36: 0124 | E36: =D36 -> 0
B37: Солиқ текширувлари натижалари бўйича қўшимча ҳисобланган солиқлар ва йиғимлар | C37: 0125 | E37: =D37 -> 0
B38: солиқ тўловчининг тадбиркорлик фаолиятини амалга ошириш билан боғлиқ бўлмаган тадбирларга (соғлиқни сақлашга оид, спорт ва маданий тадбирлар, дам олишни ташкил этиш ҳамда бошқа шунга ўхшаш тадбирларга) доир харажатлари, бундан тадбирларни ўтказишга доир мажбуриятлар қонунчилик билан солиқ тўловчининг зиммасига юклатилган ҳоллар мустасно; | C38: 0126 | E38: =D38 -> 0
B39: Маҳсулот ишлаб чиқариш билан боғлиқ бўлмаган хизматлар (шаҳарларни ва шаҳарчаларни ободонлаштириш бўйича хизматлар, қишлоқ хўжалигига ёрдамлашиш ва хизматларнинг бошқа турлари) кўрсатганлик учун қилинган харажатлар | C39: 0127 | E39: =D39 -> 0
B40: Даромад олишга қаратилган фаолият билан боғлиқ бўлмаган харажатлар, агар қонунчилик ҳужжатларига мувофиқ бундай харажатларни амалга ошириш мажбурияти солиқ тўловчининг зиммасига юклатилмаган бўлса | C40: 0128 | E40: =D40 -> 0
B41: Бюджет тизимига киритилиши лозим бўлган (киритилган) пенялар, жарималар ва бошқа санкциялар | C41: 0129 | E41: =D41 -> 0
B42: текин берилган мол-мулкнинг (хизматларнинг) қиймати ва бундай бериш билан боғлиқ бўлган (шу жумладан қўшилган қиймат солиғи суммаси киритилган) харажатлар, бундан Ўзбекистон Республикаси Президентининг ёки Ўзбекистон Республикаси Вазирлар Маҳкамасининг қарорига кўра мол-мулкни ўтказиш, шунингдек телекоммуникация тармоқларидаги тезкор-қидирув тизимининг техник воситаларини ўтказиш ва улардан фойдаланиш бўйича хизматлар кўрсатиш мустасно; | C42: 0130 | E42: =D42 -> 0
... B44: Хўжалик шартномалари шартларини бузганлик учун тўланган ёки тан олинган жарималар, пенялар ва санкцияларнинг бошқа турлари | C44: 0132 | E44: =D44 -> 0
B45: Ўзбекистон Республикаси Солиқ кодексининг 348-моддаси 2-қисмида келтирилган харажатлар | C45: 0133
B46: Ўзбекистон Республикаси халқаро шартномаси қоидаларига кўра норезидентнинг бошқарувга оид ва умуммаъмурий харажатлари (01341-сатр ёки 01342-сатр) | C46: 0134 | D46: =SUM(D47:D48) -> 0 | E46: =SUM(E47:E48) -> 0
B47: харажатларни мутаносиб равишда тақсимлаш усули | C47: 01341
B48: харажатларни чегирмаларга бевосита (тўғридан-тўғри) киритиш усули | C48: 01342
...

Sheet list04
A1: lc=R80C6
B2: Ҳисоб-китобга 2.1-илова
D3: СТИР | E3: =list01!C4 -> 0
B4: Солиқ ҳисоби маълумотларига кўра харажатлар (зарарлар) * | C4: *
B5: Солиқ солиш мақсадлари учун харажатлар (зарарлар) рўйхати | C5: Сатр коди | D5: Харажатлар (зарарлар) суммаси | E5: шундан, чегирилмайдиган харажатлар (зарарлар)
B6: 1 | C6: 2 | D6: 3 | E6: 4
B7: Жами харажатлар (020-сатр + 030-сатрлар йиғиндиси), шу жумладан: | C7: 010 | D7: =SUM(D8:D9) -> 0 | E7: =SUM(E8:E9) -> 0
B8: Сотилган товарлар (хизматлар) таннархи (Ҳисоб-китобнинг 2.1(а)-иловаси 090-сатри 5, 7-устунлари ёки 2.1(б)-иловаси 090-сатри 4, 6-устунлари) | C8: 020
B9: Жорий даврда амалга оширилган 020-сатрда кўрсатилганлардан ташқари бошқа харажатлар (0301-сатр - 0334-сатрлар суммаси), шу жумладан: | C9: 030 | D9: =SUM(D10:D49)-D16-D23-D28-D44-D48 -> 0 | E9: =SUM(E10:E49)-E16-E23-E28-E44-E48 -> 0
B10: Сарфланган хом ашё ва материаллар (0102, 0103 сатрлардан ташқари) | C10: 0301
B11: Сарфланган ёқилғи харажатлари | C11: 0302
B12: Сарфланган табиий, суюлтирилган газ харажатлари | C12: 0303
B13: Сарфланган электр энергия харажатлари | C13: 0304
B14: Меҳнатга ҳақ тўлаш харажатлари ва ижтимоий солиқ бўйича харажатлар | C14: 0305
B15: Асосий воситалар ва номоддий активлар амортизацияси | C15: 0306
B16: шу жумладан қўлланилган инвестициявий чегирма | C16: 03061
B17: Машина ва асбоб-ускуналарни жорий таъмирлаш харажатлари | C17: 0307
B18: Маркетинг ва реклама харажатлари | C18: 0308
B19: Транспорт хизмати ва ташиш харажатлари | C19: 0309
B20: Оператив ижара бўйича харажатлар | C20: 0310
B21: Мол-мулк, ер, сув ресурсларидан ҳамда ер қаъридан фойдаланганлик солиқлар | C21: 0311
... B28: Трансферт нархни белгилаш натижасида оширилган харажат суммаси * | C28: 0317
B29: Солиқ тўловчининг Солиқ кодексининг 376-моддасида назарда тутилган жисмоний шахнинг моддий наф тарзидаги даромадлари ҳисобланган харажатлари | C29: 0318 | E29: =D29 -> 0
B30: Пенсияларга устамалар ва қўшимча тўловлар | C30: 0319 | E30: =D30 -> 0
B31: Ўзбекистон Республикаси Солиқ кодексининг 377-моддаси биринчи қисми 10-бандининг тўртинчи ва бешинчи хатбошиларида кўрсатилган моддий ёрдам | C31: 0320 | E31: =D31 -> 0
B32: хайрия ёрдамини амалга ошириш учун харажатлар, бундан меценатлик кўмагини кўрсатиш, ўқув-тарбия муассасаларига ёки етим болаларга ва ота-она қарамоғидан маҳрум бўлган болаларга моддий ёрдам кўрсатиш учун йўналтирилган маблағлар, шунингдек Болаларни қўллаб-қувватлаш жамоат фондига хайрия қилинган маблағлар мустасно | C32: 0321 | E32: =D32 -> 0
B33: Айбдорлари аниқланмаган талон-тарож қилишлар ва камомадлардан ёки айбдор тараф ҳисобидан зарур суммаларнинг ўрнини қоплаш имкони бўлмаган тақдирда кўрилган зарарлар | C33: 0322 | E33: =D33 -> 0
B34: Бошқа шахслар учун тўланган солиқлар | C34: 0323 | E34: =D34 -> 0
B35: Солиқ текширувлари натижалари бўйича қўшимча ҳисобланган солиқлар ва йиғимлар | C35: 0324 | E35: =D35 -> 0
B36: солиқ тўловчининг тадбиркорлик фаолиятини амалга ошириш билан боғлиқ бўлмаган тадбирларга (соғлиқни сақлашга оид, спорт ва маданий тадбирлар, дам олишни ташкил этиш ҳамда бошқа шунга ўхшаш тадбирларга) доир харажатлари, бундан тадбирларни ўтказишга доир мажбуриятлар қонунчилик билан солиқ тўловчининг зиммасига юклатилган ҳоллар мустасно; | C36: 0325 | E36: =D36 -> 0
B37: Маҳсулот ишлаб чиқариш билан боғлиқ бўлмаган хизматлар (шаҳарларни ва шаҳарчаларни ободонлаштириш бўйича хизматлар, қишлоқ хўжалигига ёрдамлашиш ва хизматларнинг бошқа турлари) кўрсатганлик учун қилинган харажатлар | C37: 0326 | E37: =D37 -> 0
B38: Даромад олишга қаратилган фаолият билан боғлиқ бўлмаган харажатлар, агар қонунчилик ҳужжатларига мувофиқ бундай харажатларни амалга ошириш мажбурияти солиқ тўловчининг зиммасига юклатилмаган бўлса | C38: 0327 | E38: =D38 -> 0
B39: Бюджет тизимига киритилиши лозим бўлган (киритилган) пенялар, жарималар ва бошқа санкциялар | C39: 0328 | E39: =D39 -> 0
B40: текин берилган мол-мулкнинг (хизматларнинг) қиймати ва бундай бериш билан боғлиқ бўлган (шу жумладан қўшилган қиймат солиғи суммаси киритилган) харажатлар, бундан Ўзбекистон Республикаси Президентининг ёки Ўзбекистон Республикаси Вазирлар Маҳкамасининг қарорига кўра мол-мулкни ўтказиш, шунингдек телекоммуникация тармоқларидаги тезкор-қидирув тизимининг техник воситаларини ўтказиш ва улардан фойдаланиш бўйича хизматлар кўрсатиш мустасно; | C40: 0329 | E40: =D40 -> 0
... B42: Хўжалик шартномалари шартларини бузганлик учун тўланган ёки тан олинган жарималар, пенялар ва санкцияларнинг бошқа турлари | C42: 0331 | E42: =D42 -> 0
B43: Ўзбекистон Республикаси Солиқ кодексининг 348-моддаси 2-қисмида келтирилган харажатлар | C43: 0332
B44: Ўзбекистон Республикаси халқаро шартномаси қоидаларига кўра норезидентнинг бошқарувга оид ва умуммаъмурий харажатлари (03331-сатр ёки 03332-сатр) | C44: 0333 | D44: =SUM(D45:D46) -> 0 | E44: =SUM(E45:E46) -> 0
B45: харажатларни мутаносиб равишда тақсимлаш усули | C45: 03331
B46: харажатларни чегирмаларга бевосита (тўғридан-тўғри) киритиш усули | C46: 03332
B47: Ўзбекистон Республикаси Солиқ кодексининг 312-моддасига асосан илмий тадқиқотларга ва (ёки) тажриба-конструкторлик ишланмаларига доир харажатлар | C47: 0334
...

Sheet list05
B2: Бевосита харажатлар моддалари асосида товарлар (хизматлар) таннархи (ўз маҳсулоти (жу жумладан бажарилган хизматлар), сотиб олинган товарлар) ҳисоб-китоби
B3: Ҳисоб-китобга 2.1(а)-илова
H4: СТИР | I4: =+list01!C4 -> 0
B6: Реализация қилинган товарлар (хизматлар) таннархи | C6: Сатр коди | D6: Бухгалтерия ҳисоби | E6: Солиқ ҳисоби* - мутаносиб усули | H6: Солиқ ҳисоби* - тўғридан-тўғри ҳисобга олиш усули
E7: Солиқ ҳисоби коэффициенти | F7: жами харажатлар | G7: шундан, чегирилмайдиган харажатлар (зарарлар) | H7: жами харажатлар | I7: шундан, чегирилмайдиган харажатлар (зарарлар)
B8: 1 | C8: 2 | D8: 3 | E8: 4 | F8: 5 | G8: 6 | H8: 7 | I8: 8
B9: Солиқ даври бошига тугалланмаган ишлаб чиқариш қиймати (0101-0104-сатрлар йиғиндиси), шу жумладан: | C9: 010 | D9: =+SUM(D10:D13) -> 0 | E9: х | F9: =+SUM(F10:F13) -> 0 | G9: х | H9: =+SUM(H10:H13) -> 0 | I9: х
B10: Хом ашё ва материаллар | C10: 0101 | E10: х | G10: х | I10: х
B11: Меҳнатга ҳақ тўлаш харажатлари ва ижтимоий солиқ бўйича харажатлар | C11: 0102 | E11: х | G11: х | I11: х
B12: Асосий воситалар ва номоддий активларнинг амортизацияси | C12: 0103 | E12: х | G12: х | I12: х
B13: Бошқа ишлаб чиқариш харажатлари | C13: 0104 | E13: х
B14: Жорий даврда маҳсулот ишлаб чиқариш, ишлар бажариш ва хизмат кўрсатиш учун амалга оширилган чиқимлар (0201-0204-сатрлар йиғиндиси), шу жумладан: | C14: 020 | D14: =+SUM(D16:D20) -> 0 | E14: х | F14: =+SUM(F16:F20)-F19 -> 0 | G14: =+SUM(G16:G20) -> 0 | H14: =+SUM(H16:H20)-H19 -> 0 | I14: =+SUM(I16:I20) -> 0
B15: Шундан, хизмат кўрсатиш фаолият учун амалга оширилган чиқимлар | C15: 021 | E15: х
B16: Хом ашё ва материаллар | C16: 0201 | E16: х | G16: х | I16: х
B17: Меҳнатга ҳақ тўлаш харажатлари ва ижтимоий солиқ бўйича харажатлар | C17: 0202 | E17: х | G17: х | I17: х
B18: Асосий воситалар ва номоддий активларнинг амортизацияси | C18: 0203 | E18: х | G18: х | I18: х
B19: Маълумот учун: жорий даврда қўлланиладиган инвестициявий чегирмалар суммасини ўз ичига олган ҳолда | C19: 02031 | D19: х | E19: х | G19: х | I19: х
B20: Бошқа ишлаб чиқариш харажатлари | C20: 0204 | E20: х
B21: Жорий даврда маҳсулот ишлаб чиқариш, ишлар бажариш ва хизмат кўрсатиш учун амалга оширилган жами харажатлар (010-сатр + 020-сатр - 031-сатр) | C21: 030 | D21: =+SUM(D23:D26) -> 0 | E21: х | F21: =+SUM(F23:F26) -> 0 | G21: =+SUM(G23:G26) -> 0 | H21: =+SUM(H23:H26) -> 0 | I21: =+SUM(I23:I26) -> 0
B22: Ишлаб чиқариш, ишлар бажариш ва хизмат кўрсатиш учун амалга оширилган харажатлар бўйича тузатишлар *** | C22: 031 | E22: х | G22: х | I22: х
B23: Хом ашё ва материаллар | C23: 0301 | D23: =D10+D16 -> 0 | E23: х | F23: =F10+F16 -> 0 | G23: х | H23: =H10+H16 -> 0 | I23: х
B24: Меҳнатга ҳақ тўлаш харажатлари ва ижтимоий солиқ бўйича харажатлар | C24: 0302 | D24: =D11+D17 -> 0 | E24: х | F24: =F11+F17 -> 0 | G24: х | H24: =H11+H17 -> 0 | I24: х
B25: Асосий воситалар ва номоддий активларнинг амортизацияси | C25: 0303 | D25: =D12+D18 -> 0 | E25: х | F25: =F12+F18 -> 0 | G25: х | H25: =H12+H18 -> 0 | I25: х
B26: Бошқа ишлаб чиқариш харажатлари | C26: 0304 | D26: =D13+D20 -> 0 | E26: х | F26: =F13+F20 -> 0 | G26: =G13+G20 -> 0 | H26: =H13+H20 -> 0 | I26: =I13+I20 -> 0
B27: Солиқ давр охирига тугалланмаган ишлаб чиқариш қиймати ** (0401-0404-сатрлар йиғиндиси), шу жумладан: | C27: 040 | D27: =+SUM(D28:D31) -> 0 | E27: х | F27: =+SUM(F28:F31) -> 0 | G27: =+SUM(G28:G31) -> 0 | H27: =+SUM(H28:H31) -> 0 | I27: =+SUM(I28:I31) -> 0
B28: Хом ашё ва материаллар | C28: 0401 | E28: =+IFERROR(D28/D23,0) -> 0 | F28: =E28*F23 -> 0 | G28: х | I28: х
B29: Меҳнатга ҳақ тўлаш харажатлари ва ижтимоий солиқ бўйича харажатлар | C29: 0402 | E29: =+IFERROR(D29/D24,0) -> 0 | F29: =E29*F24 -> 0 | G29: х | I29: х
B30: Асосий воситалар ва номоддий активларнинг амортизацияси | C30: 0403 | E30: =+IFERROR(D30/D25,0) -> 0 | F30: =E30*F25 -> 0 | G30: х | I30: х
B31: Бошқа ишлаб чиқариш харажатлари | C31: 0404 | E31: =+IFERROR(D31/D26,0) -> 0 | F31: =E31*F26 -> 0 | G31: =E31*G26 -> 0
B32: Солиқ даври бошидаги тайёр (сотиш учун мўлжалланган) маҳсулотлар қиймати, шу жумладан: | C32: 050 | D32: =SUM(D33:D34) -> 0 | E32: х | F32: =SUM(F33:F34) -> 0 | G32: =SUM(G33:G34) -> 0 | H32: =SUM(H33:H34) -> 0 | I32: =SUM(I33:I34) -> 0
B33: Ўз ишлаб чиқарилган маҳсулотлар | C33: 0501 | E33: х
B34: Қайта сотиш учун сотиб олинган товарлар | C34: 0502 | E34: х | G34: х | I34: х
B35: Жорий даврда кирим қилинган тайёр (сотиш учун мўлжалланган) маҳсулотларнинг қиймати, шу жумладан: | C35: 060 | D35: =SUM(D36:D37) -> 0 | E35: х | F35: =SUM(F36:F37) -> 0 | G35: =SUM(G36:G37) -> 0 | H35: =SUM(H36:H37) -> 0 | I35: =SUM(I36:I37) -> 0
B36: Жорий даврда тайёр маҳсулот таннархига ҳисобдан чиқарилган тугалланмаган ишлаб чиқариш қиймати, (030-сатр - 040-сатр - 021-сатр) | C36: 0601 | D36: =D21-D27 -> 0 | E36: х | F36: =F21-F27 -> 0 | G36: =G21-G27 -> 0 | H36: =H21-H27 -> 0 | I36: =I21-I27 -> 0
B37: Қайта сотиш учун сотиб олинган товарларнинг қиймати | C37: 0602 | E37: х | G37: х | I37: х
B38: Жорий даврдаги тайёр (сотиш учун мўлжалланган) маҳсулотларнинг умумий қиймати (0701-сатр + 07011-сатр - 07012-сатр + 0702-сатр + 07021-сатр - 07022-сатр) | C38: 070 | E38: х
B39: Ўз ишлаб чиқарилган маҳсулотлар | C39: 0701 | E39: х
B40: Бошқа ҳолатлар бўйича кирим қилинган тайёр маҳсулот қиймати | C40: 07011 | E40: х | G40: х | I40: х
B41: Бошқа ҳолатлар бўйича чиқим қилинган тайёр маҳсулот қиймати **** | C41: 07012 | E41: х | G41: х | I41: х
B42: Қайта сотиш учун сотиб олинган товарлар | C42: 0702 | E42: х | I42: х
...

Sheet list06
B2: Бевосита харажатлар сумма асосида товарлар (хизматлар) таннархи (ўз маҳсулоти (жу жумладан бажарилган хизматлар), сотиб олинган товарлар) ҳисоб-китоби
B3: Ҳисоб-китобга 2.1(б)-илова
G4: СТИР | H4: =+list01!C4 -> 0
B6: Реализация қилинган товарлар (хизматлар) таннархи | C6: Сатр коди | D6: Бухгалтерия ҳисоби | E6: Солиқ ҳисоби* - мутаносиб усули | G6: Солиқ ҳисоби* - тўғридан-тўғри ҳисобга олиш усули
E7: жами харажатлар | F7: шундан, чегирилмайдиган харажатлар (зарарлар) | G7: жами харажатлар | H7: шундан, чегирилмайдиган харажатлар (зарарлар)
B8: 1 | C8: 2 | D8: 3 | E8: 4 | F8: 5 | G8: 6 | H8: 7
B9: Солиқ даври бошига тугалланмаган ишлаб чиқариш қиймати | C9: 010
B10: Жорий даврда маҳсулот ишлаб чиқариш, ишлар бажариш ва хизмат кўрсатиш учун амалга оширилган чиқимлар (0201-0204-сатрлар йиғиндиси), шу жумладан: | C10: 020 | D10: =+SUM(D12:D16) -> 0 | E10: =+SUM(E12:E16)-E15 -> 0 | F10: =+SUM(F12:F16) -> 0 | G10: =+SUM(G12:G16)-G15 -> 0 | H10: =+SUM(H12:H16) -> 0
B11: Шундан, хизмат кўрсатиш фаолият учун амалга оширилган чиқимлар | C11: 021
B12: Хом ашё ва материаллар | C12: 0201 | F12: х | H12: х
B13: Меҳнатга ҳақ тўлаш харажатлари ва ижтимоий солиқ бўйича харажатлар | C13: 0202 | F13: х | H13: х
B14: Асосий воситалар ва номоддий активларнинг амортизацияси | C14: 0203 | F14: х | H14: х
B15: Маълумот учун: жорий даврда қўлланиладиган инвестициявий чегирмалар суммасини ўз ичига олган ҳолда | C15: 02031 | D15: х | F15: х | H15: х
B16: Бошқа ишлаб чиқариш харажатлари | C16: 0204
B17: Жорий даврда маҳсулот ишлаб чиқариш, ишлар бажариш ва хизмат кўрсатиш учун амалга оширилган жами харажатлар (010-сатр + 020-сатр - 031-сатр) | C17: 030 | D17: =D9+D10 -> 0 | E17: =E9+E10 -> 0 | F17: =F9+F10 -> 0 | G17: =G9+G10 -> 0 | H17: =H9+H10 -> 0
B18: Ишлаб чиқариш, ишлар бажариш ва хизмат кўрсатиш учун амалга оширилган харажатлар бўйича тузатишлар *** | C18: 031 | F18: х | H18: х
B19: Солиқ давр охирига тугалланмаган ишлаб чиқариш қиймати ** | C19: 040 | E19: =+IFERROR(D20*E17,0) -> 0 | F19: =D20*F17 -> 0
B20: Солиқ даври охирига тугалланмаган ишлаб чиқариш қийматининг ишлаб чиқариш харажатларидаги улуши | C20: 0401 | D20: =+IFERROR(D19/D17,0) -> 0 | E20: х | F20: х | G20: х | H20: х
B21: Солиқ даври бошидаги тайёр (сотиш учун мўлжалланган) маҳсулотлар қиймати, шу жумладан: | C21: 050 | D21: =SUM(D22:D23) -> 0 | E21: =SUM(E22:E23) -> 0 | F21: =SUM(F22:F23) -> 0 | G21: =SUM(G22:G23) -> 0 | H21: =SUM(H22:H23) -> 0
B22: Ўз ишлаб чиқарилган маҳсулотлар | C22: 0501
B23: Қайта сотиш учун сотиб олинган товарлар | C23: 0502 | F23: х | H23: х
B24: Жорий даврда кирим қилинган тайёр (сотиш учун мўлжалланган) маҳсулотларнинг қиймати, шу жумладан: | C24: 060 | D24: =SUM(D25:D26) -> 0 | E24: =SUM(E25:E26) -> 0 | F24: =SUM(F25:F26) -> 0 | G24: =SUM(G25:G26) -> 0 | H24: =SUM(H25:H26) -> 0
B25: Жорий даврда тайёр маҳсулот таннархига ҳисобдан чиқарилган тугалланмаган ишлаб чиқариш қиймати, (030-сатр - 040-сатр - 021-сатр) | C25: 0601 | D25: =D17-D19 -> 0 | E25: =E17-E19 -> 0 | F25: =F17-F19 -> 0 | G25: =G17-G19 -> 0 | H25: =H17-H19 -> 0
B26: Қайта сотиш учун сотиб олинган товарларнинг қиймати | C26: 0602 | F26: х | H26: х
B27: Жорий даврдаги тайёр (сотиш учун мўлжалланган) маҳсулотларнинг умумий қиймати (0701-сатр + 07011-сатр - 07012-сатр + 0702-сатр + 07021-сатр - 07022-сатр) | C27: 070 | D27: =SUM(D28:D31) -> 0 | E27: =SUM(E28:E31) -> 0 | F27: =SUM(F28:F31) -> 0 | G27: =SUM(G28:G31) -> 0 | H27: =SUM(H28:H31) -> 0
B28: Ўз ишлаб чиқарилган маҳсулотлар | C28: 0701 | D28: =D22+D25 -> 0 | E28: =E22+E25 -> 0 | F28: =F22+F25 -> 0 | G28: =G22+G25 -> 0 | H28: =H22+H25 -> 0
B29: Бошқа ҳолатлар бўйича кирим қилинган тайёр маҳсулот қиймати | C29: 07011 | F29: х | H29: х
B30: Бошқа ҳолатлар бўйича чиқим қилинган тайёр маҳсулот қиймати *** | C30: 07012 | F30: х | H30: х
B31: Қайта сотиш учун сотиб олинган товарлар | C31: 0702 | D31: =D23+D26 -> 0 | E31: =E23+E26 -> 0 | F31: х | G31: =G23+G26 -> 0 | H31: х
B32: Бошқа ҳолатлар бўйича кирим қилинган товарлар қиймати | C32: 07021 | F32: х | H32: х
B33: Бошқа ҳолатлар бўйича чиқим қилинган товарлар қиймати *** | C33: 07022 | F33: х | H33: х
B34: Давр охирига тайёр (сотиш учун мўлжалланган) маҳсулотлар ** қиймати, шу жумладан: | C34: 080 | D34: =SUM(D35:D37) -> 0 | E34: =SUM(E35:E37) -> 0 | F34: =SUM(F35:F37) -> 0 | G34: =SUM(G35:G37) -> 0 | H34: =SUM(H35:H37) -> 0
B35: Ўз ишлаб чиқарилган маҳсулотлар | C35: 0801 | E35: =D36*E28 -> 0 | F35: =D36*F28 -> 0
B36: Тайёр маҳсулотлар қолдиғи қийматининг ишлаб чиқарилган маҳсулотлар таннархидаги улуши | C36: 08011 | D36: =+IFERROR(D35/D28,0) -> 0 | E36: х | F36: х | G36: х | H36: х
B37: Қайта сотиш учун сотиб олинган товарлар | C37: 0802 | E37: =+IFERROR(D38*E31,0) -> 0 | F37: х | H37: х
B38: Харид қилинган товарлар қолдиғи қийматининг сотиб олинган товарларнинг умумий қийматидаги улуши | C38: 08021 | D38: =+IFERROR(D37/D31,0) -> 0 | E38: х | F38: х | G38: х | H38: х
B39: Сотилган товарлар (хизматлар) таннархи | C39: 090 | D39: =SUM(D40:D41) -> 0 | E39: =SUM(E40:E41) -> 0 | F39: =SUM(F40:F41) -> 0 | G39: =SUM(G40:G41) -> 0 | H39: =SUM(H40:H41) -> 0
B40: Ўз ишлаб чиқарилган маҳсулотлар ва хизматлар (0701-сатр + 07011-сатр - 07012-сатр - 0801-сатр + 021-сатр) | C40: 0901 | D40: =D28-D35 -> 0 | E40: =E28-E35 -> 0 | F40: =F28-F35 -> 0 | G40: =G28-G35 -> 0 | H40: =H28-H35 -> 0
B41: Қайта сотиш учун сотиб олинган товарлар (0702-сатр + 07021-сатр - 07022-сатр - 0802-сатр) | C41: 0902 | D41: =D31-D37 -> 0 | E41: =E31-E37 -> 0 | F41: х | G41: =G31-G37 -> 0 | H41: х
B42: Сотилган ўзида ишлаб чиқарилган ярим тайёр маҳсулотлар, хом ашё ва материаллар | C42: 0903 | F42: х | H42: х
...

Sheet list07
A1: lc=R25C8
B2: Ҳисоб-китобга 3-илова
C3: СТИР | D3: =list01!C4 -> 0
B4: Инвестициявий чегирма ҳисоб-китоби маълумотномаси
B5: Кўрсаткич номи | C5: Сатр коди | D5: Сумма
B7: 1 | C7: 2 | D7: 3
B8: Жорий ҳисобот (солиқ) даври учун маблағларнинг инвестицияларга сарфланиши – жами (020-сатр + 030-сатр), улардан: | C8: 010 | D8: =D9+D10 -> 0
B9: янги технологик ускуналар қийматининг, ишлаб чиқаришни модернизация қилиш, техник ва (ёки) технологик жиҳатдан қайта жиҳозлаш харажатларининг ва (ёки) ахборот тизимларини яратишга доир инвестиция лойиҳалари доирасида маҳаллий ишлаб чиқаришнинг дастурий таъминотини сотиб олишга йўналтириладиган маблағлар | C9: 020
B10: ишлаб чиқаришни янги қурилиш шаклида кенгайтиришга, ишлаб чиқариш эҳтиёжлари учун фойдаланиладиган бинолар ва иншоотларни реконструкция қилишга йўналтириладиган маблағлар | C10: 030
B11: 020-сатр бўйича инвестициявий чегирма миқдори (20 фоиз) | C11: 040 | D11: =D9*0.2 -> 0
B12: 030-сатр бўйича инвестициявий чегирма миқдори (10 фоиз) | C12: 050 | D12: =D10*0.1 -> 0
B13: Жами инвестициявий чегирма миқдори (040-сатр + 050-сатр) | C13: 060 | D13: =D12+D11 -> 0
B15: Изоҳлар: 1. Мазкур илова Ўзбекистон Республика Солиқ кодексининг 308-моддасида белгиланган талаблар бўйича тўлдирилади. Инвестициявий чегирма амортизация харажати деб эътироф этилади.
B17: Раҳбар
B19: Бош бухгалтер

Sheet list08
R2: Ҳисоб-китобга 4-илова
R3: СТИР | S3: =+list01!C4 -> 0
B4: Асосий воситаларнинг амортизацияси ҳисоб-китоби маълумотномаси *
B6: Кўрсаткичлар | C6: Сатр коди | D6: I. Амортизация қилинадиган асосий воситалар | M6: II. Асосий воситаларнинг амортизацияси | R6: III. Асосий воситаларнинг қолдиқ қиймати
D7: Ҳисобот даври бошига бошланғич қиймат | E7: Солиқ даврида келиб тушган асосий воситалар | F7: Шундан | I7: Солиқ даврида асосий воситалар қийматининг ўзгариши | J7: Ижарага олувчи ижарага берувчининг розилиги билан (қарз берувчининг розилиги билан қарз олувчи) амалга оширган, қийматининг ўрни ижарага берувчи (қарз берувчи) томонидан қоплаб берилмайдиган капитал қўйилмалар | K7: Солиқ даврида фойдаланишдан чиқарилган асосий воситаларнинг қиймати | L7: Ҳисобот даври охирига амортизация қилинадиган асосий воситалар қиймати | M7: Ҳисобот даври бошига жамғарилган амортизация | N7: Солиқ даврида хисобланган амортизация | O7: Шу жумладан инвестициявий чегирма | P7: Солиқ даврида фойдаланишдан чиқарилган асосий воситалар бўйича амортизация | Q7: Ҳисобот даври охирига жамғарилган амортизация | R7: Солиқ даври бошига қолдиқ қиймат | S7: Солиқ даври охирига қолдиқ қиймат
F8: Акциядорнинг (иштирокчининг, мулкдорнинг) устав фондига (устав капиталига) ҳиссаси ҳисобига | G8: Сотиш учун мўлжалланган активлар ёки захиралар таркибидан кўчирилган | H8: Қайта ташкил этиш натижасида олинган (ҳуқуқий шаклини ўзгартириш ҳоллари бундан мустасно)
B9: 1 | C9: 2 | D9: 3 | E9: 4 | F9: 5 | G9: 6 | H9: 7 | I9: 8 | J9: 9 | K9: 10 | L9: 11=3+4+8+9-10 | M9: 12 | N9: 13 | O9: 14 | P9: 15 | Q9: 16=12+13-15 | R9: 17=3-12 | S9: 18=11-16
B10: I-гуруҳ | C10: 010 | L10: =+IF((E10+I10+J10-K10)>0,(E10+I10+J10-K10),0) -> 0 | Q10: =+IF((M10+N10-P10)>0,(M10+N10-P10),0) -> 0 | R10: =+IF((D10-M10)>0,(D10-M10),0) -> 0 | S10: =+IF((L10-Q10)>0,(L10-Q10),0) -> 0
B11: Бинолар | C11: 011 | L11: =+IF((E11+I11+J11-K11)>0,(E11+I11+J11-K11),0) -> 0 | Q11: =+IF((M11+N11-P11)>0,(M11+N11-P11),0) -> 0 | R11: =+IF((D11-M11)>0,(D11-M11),0) -> 0 | S11: =+IF((L11-Q11)>0,(L11-Q11),0) -> 0
B12: Иншоотлар | C12: 012 | L12: =+IF((E12+I12+J12-K12)>0,(E12+I12+J12-K12),0) -> 0 | Q12: =+IF((M12+N12-P12)>0,(M12+N12-P12),0) -> 0 | R12: =+IF((D12-M12)>0,(D12-M12),0) -> 0 | S12: =+IF((L12-Q12)>0,(L12-Q12),0) -> 0
B13: II-гуруҳ | C13: 020 | L13: =+IF((E13+I13+J13-K13)>0,(E13+I13+J13-K13),0) -> 0 | Q13: =+IF((M13+N13-P13)>0,(M13+N13-P13),0) -> 0 | R13: =+IF((D13-M13)>0,(D13-M13),0) -> 0 | S13: =+IF((L13-Q13)>0,(L13-Q13),0) -> 0
B14: Қувурлар, электр узатиш ва телекоммуникациялар линиялари | C14: 021 | L14: =+IF((E14+I14+J14-K14)>0,(E14+I14+J14-K14),0) -> 0 | Q14: =+IF((M14+N14-P14)>0,(M14+N14-P14),0) -> 0 | R14: =+IF((D14-M14)>0,(D14-M14),0) -> 0 | S14: =+IF((L14-Q14)>0,(L14-Q14),0) -> 0
B15: III-гуруҳ | C15: 030 | L15: =+IF((E15+I15+J15-K15)>0,(E15+I15+J15-K15),0) -> 0 | Q15: =+IF((M15+N15-P15)>0,(M15+N15-P15),0) -> 0 | R15: =+IF((D15-M15)>0,(D15-M15),0) -> 0 | S15: =+IF((L15-Q15)>0,(L15-Q15),0) -> 0
B16: Машиналар ва ускуналар (транспорт ускуналаридан ташқари) | C16: 031 | L16: =+IF((E16+I16+J16-K16)>0,(E16+I16+J16-K16),0) -> 0 | Q16: =+IF((M16+N16-P16)>0,(M16+N16-P16),0) -> 0 | R16: =+IF((D16-M16)>0,(D16-M16),0) -> 0 | S16: =+IF((L16-Q16)>0,(L16-Q16),0) -> 0
B17: IV-гуруҳ | C17: 040 | L17: =+IF((E17+I17+J17-K17)>0,(E17+I17+J17-K17),0) -> 0 | Q17: =+IF((M17+N17-P17)>0,(M17+N17-P17),0) -> 0 | R17: =+IF((D17-M17)>0,(D17-M17),0) -> 0 | S17: =+IF((L17-Q17)>0,(L17-Q17),0) -> 0
B18: Ҳаво ва космик учиш аппаратлари ва улар билан боғлиқ ускуналар, кемалар ва қайиқлар, локомотивлар ва ҳаракатдаги таркиб (темир йўл таркиби) | C18: 041 | L18: =+IF((E18+I18+J18-K18)>0,(E18+I18+J18-K18),0) -> 0 | Q18: =+IF((M18+N18-P18)>0,(M18+N18-P18),0) -> 0 | R18: =+IF((D18-M18)>0,(D18-M18),0) -> 0 | S18: =+IF((L18-Q18)>0,(L18-Q18),0) -> 0
B19: Автотранспорт воситалари, автомобиль кузовлари (корпуслари), тиркамалар ва ярим тиркамалар, бошқа транспорт ускуналари | C19: 042 | L19: =+IF((E19+I19+J19-K19)>0,(E19+I19+J19-K19),0) -> 0 | Q19: =+IF((M19+N19-P19)>0,(M19+N19-P19),0) -> 0 | R19: =+IF((D19-M19)>0,(D19-M19),0) -> 0 | S19: =+IF((L19-Q19)>0,(L19-Q19),0) -> 0
B20: V-гуруҳ | C20: 050 | L20: =+IF((E20+I20+J20-K20)>0,(E20+I20+J20-K20),0) -> 0 | Q20: =+IF((M20+N20-P20)>0,(M20+N20-P20),0) -> 0 | R20: =+IF((D20-M20)>0,(D20-M20),0) -> 0 | S20: =+IF((L20-Q20)>0,(L20-Q20),0) -> 0
B21: Компьютерлар ва периферия ускуналари | C21: 051 | L21: =+IF((E21+I21+J21-K21)>0,(E21+I21+J21-K21),0) -> 0 | Q21: =+IF((M21+N21-P21)>0,(M21+N21-P21),0) -> 0 | R21: =+IF((D21-M21)>0,(D21-M21),0) -> 0 | S21: =+IF((L21-Q21)>0,(L21-Q21),0) -> 0
... B23: Бошқа гуруҳларга киритилмаган амортизация қилинадиган активлар | C23: 061 | L23: =+IF((E23+I23+J23-K23)>0,(E23+I23+J23-K23),0) -> 0 | Q23: =+IF((M23+N23-P23)>0,(M23+N23-P23),0) -> 0 | R23: =+IF((D23-M23)>0,(D23-M23),0) -> 0 | S23: =+IF((L23-Q23)>0,(L23-Q23),0) -> 0
B25: Изоҳлар:
B26: 1. Мазкур илова Ўзбекистон Республика Солиқ кодексининг 306-моддасида белгиланган талаблар бўйича тўлдирилади.
B27: * Мазкур илова солиқ ҳисоботини йил якуни бўйича тақдим этилганда тўлдирилади.
B30: Руководитель
B32: Главный бухгалтер

Sheet list09
B2: Ҳисоб-китобга 5-илова
C3: СТИР | D3: =+list01!C4 -> 0
B4: Номоддий активлар амортизация харажатлари ҳисоб-китоби маълумотномаси *
B6: Кўрсаткичлар | C6: Сатр коди | D6: Сумма
B7: 1 | C7: 2 | D7: 3
B8: I. Амортизация қилинадиган номоддий активлар (II бандан ташқари)
B9: Нематериальные активы
B10: Номоддий активларнинг солиқ даври бошидаги қиймати | C10: 010
B11: Солиқ даврида келиб тушган номоддий активларнинг қиймати | C11: 020
B12: Солиқ даврида номоддий активлар қийматининг ўзгариши | C12: 021
B13: Солиқ даврида ҳисобдан чиқарилган номоддий активларнинг қиймати | C13: 030
B14: Номоддий активларнинг солиқ даври охиридаги қиймати (010-сатр + 020-сатр + 021-сатр - 030-сатр) | C14: 040 | D14: =IF((D10+D11+D12-D13)>0,(D10+D11+D12-D13),0) -> 0
B15: Номоддий активларнинг амортизацияси
B16: Солиқ даври бошига жамғарилган амортизация | C16: 050
B17: Солиқ даври давомида хисобланган амортизация | C17: 060
B18: Шу жумладан инвестициявий чегирма | C18: 061
B19: Солиқ даврида ҳисобдан чиқарилган номоддий активлар бўйича амортизация | C19: 062
B20: Солиқ даври охирида жамғарилган амортизация (050-сатр + 060-сатр - 062-сатр) | C20: 070 | D20: =IF((D16+D17-D19)>0,(D16+D17-D19),0) -> 0
B21: Номоддий активларнинг қолдиқ қиймати
B22: Солиқ даври бошига қолдиқ қиймат (010-сатр - 050-сатр) | C22: 080 | D22: =+IF((D10-D16)>0,(D10-D16),0) -> 0
B23: Солиқ даври охирига қолдиқ қиймат (040-сатр - 070-сатр) | C23: 090 | D23: =+IF((D14-D20)>0,(D14-D20),0) -> 0
B24: II. Фойдаланиш муддатини аниқлаш имкони бўлмаган номоддий актилар
B25: Номоддий активлар
B26: Номоддий активларнинг солиқ даври бошидаги қиймати | C26: 100
B27: Солиқ даврида келиб тушган номоддий активларнинг қиймати | C27: 110
B28: Солиқ даврида номоддий активлар қийматининг ўзгариши | C28: 111
B29: Солиқ даврида ҳисобдан чиқарилган номоддий активларнинг қиймати | C29: 120
B30: Номоддий активларнинг солиқ даври охиридаги қиймати (100-сатр + 110-сатр + 111-сатр - 120-сатр) | C30: 130 | D30: =IF((D26+D27+D28-D29)>0,(D26+D27+D28-D29),0) -> 0
B31: Номоддий активларнинг амортизацияси
B32: Солиқ даври бошига жамғарилган амортизация | C32: 140
B33: Солиқ даври давомида хисобланган амортизация | C33: 150
B34: Шу жумладан инвестициявий чегирма | C34: 151
B35: Солиқ даврида ҳисобдан чиқарилган номоддий активлар бўйича амортизация | C35: 152
B36: Солиқ даври охирида жамғарилган амортизация (140-сатр + 150-сатр - 152-сатр) | C36: 160 | D36: =IF((D32+D33-D35)>0,(D32+D33-D35),0) -> 0
B37: Номоддий активларнинг қолдиқ қиймати
B38: Солиқ даври бошига қолдиқ қиймат (100-сатр - 140-сатр) | C38: 170 | D38: =+IF((D26-D32)>0,(D26-D32),0) -> 0
B39: Солиқ даври охирига қолдиқ қиймат (130-сатр - 160-сатр) | C39: 180 | D39: =+IF((D30-D36)>0,(D30-D36),0) -> 0
B41: Изоҳлар:
B42: 1. Мазкур илова Ўзбекистон Республика Солиқ кодексининг 306 ва 307-моддасида белгиланган талаблар бўйича тўлдирилади.
B43: * Мазкур илова солиқ ҳисоботини йил якуни бўйича тақдим этилганда тўлдирилади.
...

Sheet list10
A1: lc=R35C10
B2: Ҳисоб-китобга 6-илова
E3: СТИР | F3: =list01!C4 -> 0
B4: Имтиёзлар
B5: Имтиёзлар рўйхати | D5: Сатр коди | E5: Сумма | F5: Салмоғи, %
B6: 1 | D6: 2 | E6: 3 | F6: 4
B7: Товарларни (хизматларни) реализация қилишдан олинган даромад (Ҳисоб-китобнинг 1-иловаси 020-сатри), шу жумладан | D7: 010 | E7: =list02!D8 -> 0 | F7: =IF(SUM(F8:F13)>100,"Ошибка",100) -> 100
D8: 011 | F8: =IF(E7>0,E8/E7*100,0) -> 0
D9: 012 | F9: =IF(E7>0,E9/E7*100,0) -> 0
D10: 013 | F10: =IF(E7>0,E10/E7*100,0) -> 0
D11: 014 | F11: =IF(E7>0,E11/E7*100,0) -> 0
D12: 015 | F12: =IF(E7>0,E12/E7*100,0) -> 0
D13: 016 | F13: =IF(E7>0,E13/E7*100,0) -> 0
B14: Солиқ солинадиган фойда (Ҳисоб-китобнинг 030-сатри) | D14: 020 | E14: =list01!L31 -> 0 | F14: Х
B15: Имтиёзлар – жами (040-сатр - 060-сатрлар йиғиндиси) | D15: 030 | E15: =IF(E14>0,IF(SUM(E16+E17)>E14,"Ошибка",SUM(E16+E17)),0) -> 0 | F15: Х
B16: Солиқ солинадиган фойдани ўтган солиқ даврларида олинган зарар суммасига камайтирилиши (Ҳисоб-китобнинг 8-иловаси 050-сатри) | D16: 040 | E16: =IF(list01!G6=4,list12!F17+list12!G17,0) -> 0 | F16: Х
B17: Норматив-ҳуқуқий ҳужжатлар асосида фойда солиғи бўйича имтиёзлар – жами (051 – 056-сатрлар йиғиндиси) | D17: 050 | E17: =SUM(E18:E23) -> 0 | F17: Х
D18: 051 | F18: Х
D19: 052 | F19: Х
D20: 053 | F20: Х
D21: 054 | F21: Х
D22: 055 | F22: Х
D23: 056 | F23: Х
B24: Солиқ кодекси ва бошқа норматив-ҳуқуқий ҳужжатларга мувофиқ пасайтирилган солиқ ставкаларини қўллаш тарзидаги имтиёзлар – жами (061 – 066-сатрлар йиғиндиси) | D24: 060 | E24: =SUM(E25:E30) -> 0 | F24: =IF(SUM(F25:F30)>100,"Ошибка",100) -> 100
D25: 061 | F25: =IF(E7>0,E25/E7*100,0) -> 0
D26: 062 | F26: =IF(E7>0,E26/E7*100,0) -> 0
D27: 063 | F27: =IF(E7>0,E27/E7*100,0) -> 0
D28: 064 | F28: =IF(E7>0,E28/E7*100,0) -> 0
D29: 065 | F29: =IF(E7>0,E29/E7*100,0) -> 0
D30: 066 | F30: =IF(E7>0,E30/E7*100,0) -> 0
B31: Изоҳ:
B32: 1. 4-устуннинг 011 – 013...-сатрларида кўрсатилган тушум салмоғи 3-устуннинг 011 – 013 ...-сатрларини 3-устуннинг 010-сатрига бўлиш орқали аниқланади.
B33: 2. Даромад ва харажатларни ҳисобга олишнинг тўғридан-тўғри усулини қўллайдиган солиқ тўловчилар 010 - 016-сатрларни тўлдирмайдилар;
B34: 3. 051-сатр ва кейинги сатрлар солиқ тўловчилар томонидан норматив-ҳуқуқий ҳужжатнинг тури, санаси, рақами, номи ва унинг тегишли бандини кўрсатган ҳолда тўлдирилади;
B35: 4. 061-сатр ва кейинги сатрлар солиқ тўловчилар томонидан Солиқ кодекси ва бошқа норматив-ҳуқуқий ҳужжатларга мувофиқ пасайтирилган солиқ ставкаларини қўллаш тарзидаги имтиёзлар кўрсатилади. Бунда пасайтирилган солиқ ставкаси қўлланиладиган фаолияти бўича товарларни (хизматларни) реализация қилишдан олинган даромад суммаси акс эттирилиши лозим.
B36: Раҳбар
B38: Бош бухгалтер

Sheet list11
A1: lc=R25C8
B2: Ҳисоб-китобга 7-илова
D3: СТИР | E3: =list01!C4 -> 0
B4: Ноль ставка қўлланиладиган солиқ тўловчилар фойдаси
B5: Кўрсаткичлар | C5: Сатр коди | D5: Сумма | E5: Салмоғи, %
B6: 1 | C6: 2 | D6: 3 | E6: 4
B7: Жами даромадлар (Ҳисоб-китоб 1-иловасининг 010-сатри), шу жумладан: | C7: 010 | D7: =list02!D7 -> 0 | E7: =IF((E8+E9+E10+E13)>100,"Ошибка",100) -> 100
B8: Ўзи ишлаб чиқарган ўз қишлоқ хўжалиги маҳсулотини реализация қилишдан олинган даромад | C8: 011 | E8: =IF(D8>0,D8/D7*100,0) -> 0
B9: Ижтимоий соҳада фаолиятни амалга оширишдан олинган даромад | C9: 012 | E9: =IF(D9>0,D9/D7*100,0) -> 0
B10: Қўшимча манбалардан даромадлар олувчи бюджет ташкилотлари | C10: 013 | E10: =IF(D10>0,D10/D7*100,0) -> 0
B11: Ягона иштирокчилари ногиронлиги бўлган шахсларнинг жамоат бирлашмалари бўлган ва умумий ходимлар сонида ногиронлиги бўлган шахслар камида 50 фоизни ташкил этадиган ва ногиронлиги бўлган шахсларнинг меҳнатига ҳақ тўлаш жамғармаси меҳнатга ҳақ тўлаш умумий фондининг камида 50 фоизини ташкил этадиган солиқ тўловчилар | C11: 014 | E11: Х
B12: Халқ банки томонидан фуқароларнинг шахсий жамғариб бориладиган пенсия ҳисобварақларидаги маблағлардан фойдаланишдан олинадиган даромадлар | C12: 015 | E12: Х
B13: Умумий куввати 100 кВтгача бўлган кайта тикланувчи энергия манбалари курилмаларидан фойдаланган ҳолда умумий тармокка электр энергиясини реализация қилишдан олинган даромад | C13: 016 | E13: =IF(D13>0,D13/D7*100,0) -> 0
B14: Солиқ солинадиган фойда ((Ҳисоб-китобнинг 030-сатри) | C14: 020 | D14: =IF(list01!L31<0,0,list01!L31) -> 0 | E14: Х
B15: шундан, ноль ставкаси қўлланиладиган фойда жами (031-сатр - 036-сатрлар йиғиндиси) | C15: 030 | D15: =IF(SUM(D16:D21)>D14,"Ошибка",SUM(D16:D21)) -> 0 | E15: Х
B16: Қишлоқ хўжалиги товар ишлаб чиқарувчилари ва балиқ хўжалиги | C16: 031 | E16: =IF(ISBLANK(D16),0,IF(E8>79.99,0,"Ошибка")) -> 0
B17: Ижтимоий соҳада фаолиятни амалга оширишдан олинган фойда | C17: 032 | E17: =IF(ISBLANK(D17),0,IF(E9>89.99,0,"Ошибка")) -> 0
B18: Қўшимча манбалардан даромадлар олувчи бюджет ташкилотлари | C18: 033 | E18: Х
B19: Ягона иштирокчилари ногиронлиги бўлган шахслар бўлган солиқ тўловчилар (014-сатр бўйича) | C19: 034 | E19: Х
B20: Халқ банки томонидан фуқароларнинг шахсий жамғариб бориладиган пенсия ҳисобварақларидаги маблағлардан фойдаланишдан олинган фойда | C20: 035 | E20: Х
B21: Умумий куввати 100 кВтгача бўлган кайта тикланувчи энергия манбалари курилмаларидан фойдаланган ҳолда умумий тармокка электр энергиясини реализация қилишдан олинган фойда | C21: 036 | E21: Х
B22: Изоҳлар:
B23: 1. Мазкур илова Ўзбекистон Республикаси Солиқ кодексининг 337-моддасида белгиланган шартларга жавоб берган ҳолларда тўлдирилади;
B24: 2. 033-сатр, 035, 036-сатрларда даромад ва харажатларни ҳисобга олишнинг қўлланилаётган (тўғридан-тўғри ёки мутаносиб) усулига мувофиқ тўлдирилади.
B25: Раҳбар
B27: Бош бухгалтер

Sheet list12
A1: lc=R45C8
B2: Ҳисоб-китобга 8-илова
F3: СТИР | G3: =+list01!C4 -> 0
B4: Жорий солиқ давридаги солиқ солинадиган фойдани камайтирадиган ўтган йиллар зарари суммасининг ҳисоб-китоби
B5: Кўрсаткичлар | E5: Сатр коди | F5: 2020 йил 1 январга қадар ҳосил бўлган зарарлар | G5: 2020 йил 1 январдан кейин ҳосил бўлган зарарлар
B6: 1 | E6: 2 | F6: 3 | G6: 4
B7: Жорий солиқ даврининг боши ҳолатига ўтказилмаган зарар қолдиғи – жами (0101 – 0105-сатрлар йиғиндиси) | E7: 010 | F7: =SUM(F9:F13) -> 0
B8: шу жумладан, қуйидаги йиллар учун олинган зарар:
D9: йил учун (ўтган солиқ даври учун Ҳисоб-китобнинг 8-иловаси 0601-сатридан) | E9: 0101 | G9: x
D10: йил учун (ўтган солиқ даври учун Ҳисоб-китобнинг 8-иловаси 0602-сатридан) | E10: 0102 | G10: x
D11: йил учун (ўтган солиқ даври учун Ҳисоб-китобнинг 8-иловаси 0603-сатридан) | E11: 0103 | G11: x
D12: йил учун (ўтган солиқ даври учун Ҳисоб-китобнинг 8-иловаси 0604-сатридан) | E12: 0104 | G12: x
D13: йил учун (ўтган солиқ даври учун Ҳисоб-китобнинг 8-иловаси 0605-сатридан) | E13: 0105 | G13: x
B14: Жорий йилда олинган зарар (Ҳисоб-китобнинг (010-сатри - 020-сатри)) | E14: 020 | F14: =IF(list01!L31<0,ABS(list01!L31),0) -> 0 | G14: =IF(list01!L31<0,ABS(list01!L31),0) -> 0
B15: Солиқ солинадиган фойда (Ҳисоб-китобнинг 030-сатри), бироқ “0”дан кам эмас | E15: 030 | F15: =IF(list01!L31<0,0,list01!L31) -> 0 | G15: =IF(list01!L31<0,0,list01!L31) -> 0
B16: Жорий солиқ даврида солиқ солинадиган фойдани зарар ёки зарарнинг бир қисмига камайтириладиган энг юқори суммаси (3-устун 030-сатр х 50%) | E16: 040 | F16: =ROUND(F15/2,2) -> 0
B17: Жорий солиқ даврининг солиқ солинадиган фойдасини камайтирадиган зарар ёки зарарнинг бир қисми суммаси (010-сатр, бироқ 040-сатрдан ошмаган миқдорда) | E17: 050 | F17: =IF(F7<F16,F7,F16) -> 0 | G17: =IF(G7<G16,G7,G16) -> 0
B18: Жорий солиқ даврининг охирига ўтказилмаган зарарнинг қолдиғи – жами (0601 – 0605-сатрлар йиғиндиси), шу жумладан: | E18: 060 | F18: =SUM(F19:F23) -> 0 | G18: =+G7-G17+G14 -> 0
D19: йил учун (0101-сатр суммасидан) | E19: 0601 | G19: x
D20: йил учун (0102-сатр суммасидан) | E20: 0602 | G20: x
D21: йил учун (0103-сатр суммасидан) | E21: 0603 | G21: x
D22: йил учун (0104-сатр суммасидан) | E22: 0604 | G22: x
D23: йил учун (0105-сатр суммасидан) | E23: 0605 | G23: x
B24: Изоҳлар:
B25: 1. Агар 020-сатр миқдори «0»дан катта ёки тенг бўлса, мазкур сатрда «0» қўйилади. 020-сатрда акс эттириладиган зарар «–» белгисиз кўрсатилади.
B26: 2. 3-устуннинг 0601 – 0605-сатри суммалари 050-сатр суммасини кетма-кетлик тарзида 0101-0105-сатрлар суммасидан чегириш натижасида шакллантирилади.
B27: 3. Мазкур Ҳисоб-китоб солиқ ҳисоботини йил якуни бўйича тақдим этилганда тўлдирилади.
D29: Раҳбар
D31: Бош бухгалтер

Sheet list13
A1: lc=R45C15
B2: Ҳисоб-китобга 9-илова
J3: СТИР | K3: =list01!C4 -> 0
B4: Операцияларнинг айрим турлари бўйича зарарларни ўтказишнинг ўзига хос хусусиятлари
B5: Кўрсаткичлар | E5: Сатр коди | F5: Юридик шахснинг устав фондида (устав капиталида) иштирок этиш улушини реализация қилишдан ёки унинг бошқача тарзда чиқиб кетиши | G5: Сотувчи томонидан корхонани мол-мулк мажмуи сифатидаги сотишдан операциялар буйича | H5: Ишончли бошқарув шартномаси бўйича ишончли бошқарув муассиси ёки наф олувчиси томонидан олинган операциялар буйича | I5: Оддий ширкат шартномасида (биргаликдаги фаолият тўғрисидаги шартномада) иштирок этишдан шерикнинг (иштирокчининг) операциялар буйича олинган операциялар буйича | J5: Хизмат кўрсатувчи хўжаликлардан операциялар буйича | K5: Муомалада бўлмаган қимматли қоғозлар ва муддатли битимларнинг муомалада бўлмаган молиявий воситаларига доир операциялар буйича
B6: 1 | E6: =+B6+1 -> 2 | F6: =+E6+1 -> 3 | G6: =+F6+1 -> 4 | H6: =+G6+1 -> 5 | I6: =+H6+1 -> 6 | J6: =+I6+1 -> 7 | K6: =+J6+1 -> 8
B7: Ўтган солиқ даврларида айрим операциялар буйича қопланмаган қолдиғи | E7: 010
B8: Солиққа тортиладиган даромадлар | E8: 020
B9: Жами харажатлар | E9: 030
B10: шу жумладан, чегирилмайдиган харажатлар | E10: 040
B11: Ҳисобот (солиқ) даврида солиқ солинадиган фойда (020-сатр - 030-сатр + 040-сатр), бироқ "0" дан кам эмас | E11: 050 | F11: =IF((F8-F9+F10)>0,(F8-F9+F10),0) -> 0 | G11: =IF((G8-G9+G10)>0,(G8-G9+G10),0) -> 0 | H11: =IF((H8-H9+H10)>0,(H8-H9+H10),0) -> 0 | I11: =IF((I8-I9+I10)>0,(I8-I9+I10),0) -> 0 | J11: =IF((J8-J9+J10)>0,(J8-J9+J10),0) -> 0 | K11: =IF((K8-K9+K10)>0,(K8-K9+K10),0) -> 0
B12: Жорий солиқ даврида кўрилган зарар (020-сатр - 030-сатр +040 сатр) | E12: 060 | F12: =IF((F8-F9+F10)<0,(F8-F9+F10),0) -> 0 | G12: =IF((G8-G9+G10)<0,(G8-G9+G10),0) -> 0 | H12: =IF((H8-H9+H10)<0,(H8-H9+H10),0) -> 0 | I12: =IF((I8-I9+I10)<0,(I8-I9+I10),0) -> 0 | J12: =IF((J8-J9+J10)<0,(J8-J9+J10),0) -> 0 | K12: =IF((K8-K9+K10)<0,(K8-K9+K10),0) -> 0
B13: Ҳисобот (солиқ) даври учун солиқ базасини оширадиган фойда суммаси жами (050-сатр - 010-сатр), бироқ "0" дан кам эмас | E13: 070 | F13: =IF((F11-F7)>0,(F11-F7),0) -> 0 | G13: =IF((G11-G7)>0,(G11-G7),0) -> 0 | H13: =IF((H11-H7)>0,(H11-H7),0) -> 0 | I13: =IF((I11-I7)>0,(I11-I7),0) -> 0 | J13: =IF((J11-J7)>0,(J11-J7),0) -> 0 | K13: =IF((K11-K7)>0,(K11-K7),0) -> 0
B14: Жорий ҳисобот (солиқ) даврида айрим операциялар буйича қопланмаган қолдиғи | E14: 080
B15: Мазкур илова Ўзбекистон Республикаси Солиқ кодексининг 336-моддасида белгиланган талаблар асосида тўлдириади
D16: Раҳбар
D18: Бош бухгалтер

Sheet list14
A1: lc=R25C5
B2: Ҳисоб-китобга 10-илова
C3: СТИР | D3: =list01!C4 -> 0
B4: Ҳисобга олинадиган Ўзбекистон Республикасидан ташқарида тўланган фойда солиғи суммаси
B5: Кўрсаткичлар | C5: Сатр коди | D5: Сумма
B6: Ўзбекистон Республикасидан ташқарида олинган жами даромад суммаси (дивидендлардан ташқари) | C6: 010
B7: Ўзбекистон Республикасидан ташқарида олинган даромаддан тўланган солиқ суммаси (дивидендлар кўринишидаги даромадлардан тўланган солиқдан ташқари) | C7: 020
B8: Жами даромадлар (Ҳисоб-китобнинг 010-сатри) | C8: 030 | D8: =list02!D7 -> 0
B9: Ўзбекистон Республикасидан ташқарида олинган даромаднинг жами даромаддаги улуши, фоизда (010-сатр / 030-сатр × 100) | C9: 040 | D9: =IF(D8>0,(D6/D8*100),0) -> 0
B10: Солиқ базаси (Ҳисоб-китобнинг 060-сатри) | C10: 050 | D10: =IF(list01!L34<0,0,list01!L34) -> 0
B11: Ўзбекистон Республикасидан ташқарида олинган даромад қисмида солиқ солиниши лозим бўлган фойда суммаси (050-сатр × 040-сатр) | C11: 060 | D11: =D10*D9/100 -> 0
B12: Фойда солиғи ставкаси (Ҳисоб-китобнинг 070-сатри) | C12: 070 | D12: =list01!L36 -> 0
B13: Фойда солиғи суммаси (060-сатр × 070-сатр) | C13: 080 | D13: =D11*D12/100 -> 0
B14: Ҳисобга олинадиган фойда солиғи | C14: 090 | D14: =IF(D7>D13,D13,D7) -> 0
B15: Изоҳлар:
B16: 1. Агар 020-сатр миқдори: 080-сатр миқдоридан катта бўлса, 090-сатрда 080-сатр қиймати қўйилади; 080-сатр миқдоридан кичик ёки тенг бўлса, 090-сатрда 020-сатр қиймати қўйилади.
B17: 2. Ҳисоб-китобга Ўзбекистон Республикасидан ташқарида олинган даромаддан тўланган солиқ суммасини ҳисобга олиш учун чет давлат ваколатли органининг тўлов хабарномаси, маълумотномаси ёки солиқ тўланганлигини тасдиқловчи бошқа ҳужжат илова қилинади.
B18: Раҳбар
B20: Бош бухгалтер

Sheet list15
A1: lc=R35C5
B2: Ҳисоб-китобга 11-илова
C3: СТИР | D3: =list01!C4 -> 0
B4: Ўзбекистон Республикаси резидентлари томонидан Ўзбекистон Республикасидан ташқарида олинган дивидендлар кўринишидаги даромадлардан фойда солиғининг ҲИСОБ-КИТОБ-МАЪЛУМОТНОМАСИ
B5: Кўрсаткичлар | C5: Сатр коди | D5: Сумма
B6: Ўзбекистон Республикасидан ташқарида олиниши лозим бўлган (олинган) дивидендлар суммаси - жами (011-сатр + 012-сатр), шу жумладан: | C6: 010 | D6: =D7+D12 -> 0
B7: иккиёқлама солиқ солишнинг олдини олиш тўғрисида битим мавжуд бўлган мамлакатлардан (0111-сатр + 0121-сатр): | C7: 011 | D7: =D8+D10 -> 0
B8: белгиланган ставкадан паст ёки тенг ставкада солиқ солинадиган | C8: 0111
B9: улардан жорий ҳисобот (солиқ) даврида ҳақиқатда олинган (0111-сатрдан) | C9: 0112
B10: белгиланган ставкадан юқори ставкада солиқ солинадиган | C10: 0121
B11: улардан жорий ҳисобот (солиқ) даврида ҳақиқатда олинган (0121-сатрдан) | C11: 0122
B12: иккиёқлама солиқ солишнинг олдини олиш тўғрисида битим мавжуд бўлмаган мамлакатлардан | C12: 012
B13: Иккиёқлама солиқ солишнинг олдини олиш тўғрисида битим бўйича солиқ солинадиган ўтган солиқ даврларида ҳисобланган ва жорий ҳисобот (солиқ) даврида ҳақиқатда тўланган дивидендлар (021-сатр + 022-сатр): | C13: 020 | D13: =D14+D15 -> 0
B14: белгиланган ставкадан паст ёки тенг ставка бўйича | C14: 021
B15: белгиланган ставкадан юқори ставка бўйича | C15: 022
B16: Дивидендлар тарзидаги даромадлардан олинадиган солиқнинг белгиланган ставкаси, фоизда | C16: 030
B17: Олинган дивиденд тарзидаги даромадлардан олинадиган солиқ суммаси (010-сатр х 030-сатр), шу жумладан: | C17: 040 | D17: =D6*D16 -> 0
B18: 0111-сатрда кўрсатилган дивидендлар бўйича (0111-сатр х 030-сатр) | C18: 041 | D18: =D8*D16 -> 0
B19: 0121-сатрда кўрсатилган дивидендлар бўйича (0121-сатр х 030-сатр) | C19: 042 | D19: =D10*D16 -> 0
B20: 012-сатрда кўрсатилган дивидендлар бўйича (012-сатр х 030-сатр) | C20: 043 | D20: =D12*D16 -> 0
B21: Иккиёқлама солиқ солишнинг олдини олиш тўғрисида битимга мувофиқ ҳисобга олинадиган Ўзбекистон Республикасидан ташқарида солиқ тўланганлигини тасдиқловчи ҳужжатлар мавжуд солиқ суммаси (051-сатр + 052-сатр + 053-сатр + 054-сатр): | C21: 050 | D21: =D22+D23+D24+D25 -> 0
B22: 0112-сатрда кўрсатилган дивидендлардан | C22: 051
B23: 0122-сатрда кўрсатилган дивидендлардан (0122-сатр х 030-сатр) | C23: 052 | D23: =D11*D16 -> 0
B24: 021-сатрда кўрсатилган дивидендлардан | C24: 053
B25: 022-сатрда кўрсатилган дивидендлардан (022-сатр х 030-сатр) | C25: 054 | D25: =D15*D16 -> 0
B26: Фойда солиғининг бюджетга тўланиши лозим бўлган суммаси (+) ёки камайтириладиган суммаси (–) (040-сатр – 050-сатр) | C26: 060 | D26: =D17-D21 -> 0
B28: Изоҳ:
B29: 1. 020-сатрда тегишлича Ўзбекистон Республикаси Солиқ кодексининг 88-моддасида белгиланган даъво қилиш муддати ичида иккиёқлама солиқ солишнинг олдини олиш тўғрисида битим мавжуд бўлган мамлакатлардан олинган дивидендлар кўрсатилади.
B30: 2. Маълумотнома-ҳисоб-китобга Ўзбекистон Республикасидан ташқарида олинган даромаддан тўланган солиқ суммасини ҳисобга олиш учун чет давлат ваколатли органининг тўлов хабарномаси, маълумотномаси ёки солиқ тўланганлигини тасдиқловчи бошқа ҳужжат илова қилинади.
B31: Раҳбар
B33: Бош бухгалтер

Sheet list16
B2: Ҳисоб-китобга 12-илова
E3: СТИР | F3: =list01!C4 -> 0
B4: Солиқ кодексининг 177-моддасига мувофиқ солиқ тўловчи томонидан солиқ базасига ва (ёки) солиқнинг (зарарнинг) суммасига мустақил равишда тузатишлар киритилиши тўғрисида маълумот
B54: Изоҳ: Солиқ базасига ва (ёки) солиқ суммасига мустақил равишда тузатиш киритишга асос бўлган хар бир битим юзасидан маълумотлар кўрсатилади.
B55: Раҳбар
B57: Бош бухгалтер
